Workbook

Sheet Market prices
A1: MARKET SURVEY - Greenhouse Project
A2: Pieces per kg is for vegetables that are not being sold as a single item e.g. cups and display. The purpose of pieces per kg is to standardize price
A3: Market | B3: Vegetable | C3: Size (Small/Medium/Large) | D3: Unit Observed | E3: Count per Unit (# of pieces) | F3: Price per Unit | G3: Price for each | H3: Pieces per kg | I3: NLE per kg | J3: Notes | K3: Surveyed by
A4: TormaBum | B4: Tomato | C4: small | D4: display | E4: 10 | F4: 10 | G4: =F4/E4 -> 1 | H4: ='Weighing Reference'!E6 -> 13.574661 | I4: =H4*G4 -> 13.574661 | K4: Ronald
A5: TormaBum | B5: Tomato | C5: medium | D5: display | E5: 12 | F5: 20 | G5: =F5/E5 -> 1.6666667 | H5: ='Weighing Reference'!E7 -> #DIV/0! | I5: =H5*G5 -> #DIV/0! | K5: Ronald
A6: TormaBum | B6: Okra | C6: - | D6: bag | E6: 1 | F6: 875 | G6: =F6/E6 -> 875 | H6: - | I6: - | K6: Ronald
A7: TormaBum | B7: Okra | C7: any | D7: display | E7: 12 | F7: 5 | G7: =F7/E7 -> 0.41666667 | H7: ='Weighing Reference'!E17 -> 63.492063 | I7: =H7*G7 -> 26.455026 | K7: Ronald
A8: TormaBum | B8: Local Hot Pepper | C8: - | D8: bag | E8: 1 | F8: 300 | G8: =F8/E8 -> 300 | H8: - | I8: - | K8: Ronald
A9: TormaBum | B9: Local Hot Pepper | C9: - | D9: cup | E9: 1 | F9: 5 | G9: =F9/E9 -> 5 | H9: ='Weighing Reference'!E26 -> 7.3529412 | I9: =H9*G9 -> 36.764706 | K9: Ronald
A10: TormaBum | B10: Habanero Pepper | C10: - | D10: bowl | E10: 1 | F10: 20 | G10: =F10/E10 -> 20 | H10: - | I10: - | K10: Ronald
A11: TormaBum | B11: Habanero Pepper | C11: - | D11: cup | E11: 1 | F11: 5 | G11: =F11/E11 -> 5 | H11: ='Weighing Reference'!E28 -> 8.5470085 | I11: =H11*G11 -> 42.735043 | K11: Ronald
A12: TormaBum | B12: Carrot | C12: any | D12: display | E12: 6 | F12: 20 | G12: =F12/E12 -> 3.3333333 | H12: ='Weighing Reference'!E19 -> 8.1967213 | I12: =H12*G12 -> 27.322404 | K12: Ronald
A13: TormaBum | B13: Cucumber | C13: small | D13: display | E13: 12 | F13: 10 | G13: =F13/E13 -> 0.83333333 | H13: - | I13: - | K13: Ronald
A14: TormaBum | B14: Cucumber | C14: medium | D14: display | E14: 10 | F14: 10 | G14: =F14/E14 -> 1 | H14: ='Weighing Reference'!E16 -> 7.0422535 | I14: =H14*G14 -> 7.0422535 | K14: Ronald
A15: TormaBum | B15: Garden Eggs | C15: - | D15: bag | E15: 1 | F15: 250 | G15: =F15/E15 -> 250 | H15: - | I15: - | K15: Ronald
A16: TormaBum | B16: Garden Eggs | C16: any | D16: display | E16: 18 | F16: 2 | G16: =F16/E16 -> 0.11111111 | H16: ='Weighing Reference'!E13 -> 16.042781 | I16: =H16*G16 -> 1.7825312 | K16: Ronald
A17: TormaBum | B17: Eggplant | C17: - | D17: bag | E17: 1 | F17: 300 | G17: =F17/E17 -> 300 | I17: =H17*G17 -> 0 | K17: Ronald
A18: TormaBum | B18: Eggplant | C18: small | D18: display | E18: 5 | F18: 2 | G18: =F18/E18 -> 0.4 | I18: =H18*G18 -> 0 | K18: Ronald
A19: TormaBum | B19: Eggplant | C19: medium | D19: display | E19: 20 | F19: 5 | G19: =F19/E19 -> 0.25 | H19: ='Weighing Reference'!E10 -> 9.1954023 | I19: =H19*G19 -> 2.2988506 | K19: Ronald | N19: Prices for eggplants and gardens need to be revisited
A20: TormaBum | B20: Krainkrain | C20: - | D20: tie | E20: 1 | F20: 5 | G20: =F20/E20 -> 5 | H20: ='Weighing Reference'!E25 -> 2 | I20: =H20*G20 -> 10 | K20: Ronald
A21: Bo | B21: Tomato | C21: - | D21: crate | E21: 1 | F21: 925 | G21: =F21/E21 -> 925 | I21: =H21*G21 -> 0 | K21: Muhammad
A22: Bo | B22: Tomato | C22: small | D22: display | E22: 6 | F22: 10 | G22: =F22/E22 -> 1.6666667 | H22: ='Weighing Reference'!E6 -> 13.574661 | I22: =H22*G22 -> 22.624434 | K22: Muhammad
A23: Bo | B23: Tomato | C23: medium | D23: display | E23: 8 | F23: 20 | G23: =F23/E23 -> 2.5 | I23: =H23*G23 -> 0 | K23: Muhammad
A24: Bo | B24: Okra | C24: any | D24: display | E24: 6 | F24: 5 | G24: =F24/E24 -> 0.83333333 | H24: ='Weighing Reference'!E17 -> 63.492063 | I24: =H24*G24 -> 52.910053 | K24: Muhammad
A25: Bo | B25: Local Hot Pepper | C25: - | D25: cup | E25: 1 | F25: 7 | G25: =F25/E25 -> 7 | H25: ='Weighing Reference'!E26 -> 7.3529412 | I25: =H25*G25 -> 51.470588 | K25: Muhammad
A26: Bo | B26: Habanero Pepper | C26: - | D26: display | E26: 9 | F26: 5 | G26: =F26/E26 -> 0.55555556 | H26: ='Weighing Reference'!E27 -> 184.21053 | I26: =H26*G26 -> 102.33918 | K26: Muhammad
A27: Bo | B27: Carrot | C27: - | D27: bag | E27: 1 | F27: 1100 | G27: =F27/E27 -> 1100 | I27: =H27*G27 -> 0 | K27: Muhammad
A28: Bo | B28: Carrot | C28: any | D28: display | E28: 8 | F28: 10 | G28: =F28/E28 -> 1.25 | H28: ='Weighing Reference'!E19 -> 8.1967213 | I28: =H28*G28 -> 10.245902 | K28: Muhammad
A29: Bo | B29: Cucumber | C29: small | D29: display | E29: 12 | F29: 10 | G29: =F29/E29 -> 0.83333333 | H29: ='Weighing Reference'!E16 -> 7.0422535 | I29: =H29*G29 -> 5.8685446 | K29: Muhammad
A30: Bo | B30: Garden Eggs | C30: any | D30: display | E30: 5 | F30: 4 | G30: =F30/E30 -> 0.8 | H30: ='Weighing Reference'!E13 -> 16.042781 | I30: =H30*G30 -> 12.834225 | K30: Muhammad
A31: Bo | B31: Cabbage | C31: - | D31: bag | E31: 1 | F31: 875 | G31: =F31/E31 -> 875 | I31: =H31*G31 -> 0 | K31: Muhammad
A32: Bo | B32: Cabbage | C32: - | D32: single | E32: 1 | F32: 35 | G32: =F32/E32 -> 35 | I32: =H32*G32 -> 0 | K32: Muhammad
A33: Bo | B33: Eggplant | C33: - | D33: bag | E33: 1 | F33: 700 | G33: =F33/E33 -> 700 | I33: =H33*G33 -> 0 | K33: Muhammad
A34: Bo | B34: Eggplant | C34: small | D34: display | E34: 16 | F34: 2 | G34: =F34/E34 -> 0.125 | I34: =H34*G34 -> 0 | K34: Muhammad
A35: Bo | B35: Eggplant | C35: medium | D35: display | E35: 6 | F35: 4 | G35: =F35/E35 -> 0.66666667 | H35: ='Weighing Reference'!E10 -> 9.1954023 | I35: =H35*G35 -> 6.1302682 | K35: Muhammad
A36: Bo | B36: Krainkrain | C36: - | D36: tie | E36: 1 | F36: 7 | G36: =F36/E36 -> 7 | H36: ='Weighing Reference'!E25 -> 2 | I36: =H36*G36 -> 14 | K36: Muhammad
A37: Waterloo | B37: Tomato | C37: - | D37: sheba rubbers | E37: 1 | F37: 1800 | G37: =F37/E37 -> 1800 | I37: =H37*G37 -> 0 | K37: Ousman
A38: Waterloo | B38: Tomato | C38: small | D38: display | E38: 12 | F38: 50 | G38: =F38/E38 -> 4.1666667 | H38: ='Weighing Reference'!E6 -> 13.574661 | I38: =H38*G38 -> 56.561086 | K38: Ousman
A39: Waterloo | B39: Tomato | C39: medium | D39: display | E39: 3 | F39: 20 | G39: =F39/E39 -> 6.6666667 | I39: =H39*G39 -> 0 | K39: Ousman
A40: Waterloo | B40: Okra | C40: - | D40: sheba rubbers | E40: 1 | F40: 300 | G40: =F40/E40 -> 300 | I40: =H40*G40 -> 0 | K40: Ousman
...

Sheet Daily Sales Record
A1: e
A2: Pieces per kg is for vegetables that are not being sold as a single item e.g. cups and display. The purpose of pieces per kg is to standardize price
A3: Date | B3: Market | C3: Vegetable | D3: Quantity Delivered (kg) | E3: Quantity Sold (kg) | F3: kg Spoiled/Loss | G3: Loss % | H3: Balance | I3: Units Sold in | J3: Units Sold | K3: Price per Unit (NLE) | L3: Total Revenue (NLE) | M3: Transport Cost (NLE) | N3: Net Revenue (NLE) | O3: NLE per Kg earned | P3: Notes
A4: 46113 | B4: Bo | C4: Habanero Hot Pepper | D4: 2 | E4: 2 | F4: =D4-E4 -> 0 | G4: =F4/D4 -> 0 | H4: =D4-E4-F4 -> 0 | I4: places | J4: 35 | K4: 5 | L4: =J4*K4 -> 175 | N4: =L4-M4 -> 175 | O4: =N4/E4 -> 87.5
A5: 46113 | B5: Bo | C5: Garden Eggs | D5: 5 | E5: 5 | F5: =D5-E5 -> 0 | G5: =F5/D5 -> 0 | H5: =D5-E5-F5 -> 0 | I5: places | J5: 21.25 | K5: 4 | L5: =J5*K5 -> 85 | N5: =L5-M5 -> 85 | O5: =N5/E5 -> 17
A6: 46113 | B6: Bo | C6: Eggplant | D6: 11 | E6: 10.5 | F6: =D6-E6 -> 0.5 | G6: =F6/D6 -> 0.045454545 | H6: =D6-E6-F6 -> 0 | I6: places | J6: 22 | K6: 2 | L6: =J6*K6 -> 44 | N6: =L6-M6 -> 44 | O6: =N6/E6 -> 4.1904762
A7: 46113 | B7: Bo | C7: Local Hot Pepper | D7: 3 | E7: 3 | F7: =D7-E7 -> 0 | G7: =F7/D7 -> 0 | H7: =D7-E7-F7 -> 0 | I7: cups | J7: 20 | K7: 7 | L7: =J7*K7 -> 140 | N7: =L7-M7 -> 140 | O7: =N7/E7 -> 46.666667
A8: 46122 | B8: TormaBum | C8: Local Hot Pepper | D8: 1 | E8: 1 | F8: 0 | G8: 0 | H8: =D8-E8-F8 -> 0 | I8: cups | J8: 2 | K8: 5 | L8: =J8*K8 -> 10 | M8: 0 | N8: =L8-M8 -> 10 | O8: =N8/E8 -> 10
A9: 46125 | B9: TormaBum | C9: Garden Eggs | D9: 3 | E9: 2 | F9: 0 | G9: 0 | H9: =D9-E9-F9 -> 1 | I9: places | J9: 4 | K9: 2 | L9: =J9*K9 -> 8 | M9: 0 | N9: =L9-M9 -> 8 | O9: =N9/E9 -> 4 | P9: find out what happened to the balance, and is that all that was made?
A10: 46125 | B10: TormaBum | C10: Eggplant | D10: 5 | E10: 5 | F10: 0 | G10: 0 | H10: =D10-E10-F10 -> 0 | I10: places | J10: 5 | K10: 2 | L10: =J10*K10 -> 10 | M10: 0 | N10: =L10-M10 -> 10 | O10: =N10/E10 -> 2
A11: 46125 | B11: TormaBum | C11: Local Hot Pepper | D11: 2.6 | E11: 2.6 | F11: 0 | G11: 0 | H11: =D11-E11-F11 -> 0 | I11: cups | J11: 6 | K11: 5 | L11: =J11*K11 -> 30 | M11: 0 | N11: =L11-M11 -> 30 | O11: =N11/E11 -> 11.538462
A12: 46132 | B12: TormaBum | C12: Garden Eggs | D12: 3 | E12: 3 | F12: 0 | G12: 0 | H12: =D12-E12-F12 -> 0 | I12: places | J12: 5 | K12: 2 | L12: =J12*K12 -> 10 | M12: 0 | N12: =L12-M12 -> 10 | O12: =N12/E12 -> 3.3333333
A13: 46132 | B13: TormaBum | C13: Eggplant | D13: 4 | E13: 2 | F13: 0 | G13: 0 | H13: =D13-E13-F13 -> 2 | I13: places | J13: 3 | K13: 2 | L13: =J13*K13 -> 6 | M13: 0 | N13: =L13-M13 -> 6 | O13: =N13/E13 -> 3 | P13: balace used for multiplication
A14: 46132 | B14: TormaBum | C14: Local Hot Pepper | D14: 0.5 | E14: 0.5 | G14: 0 | H14: =D14-E14-F14 -> 0 | I14: cups | J14: 2 | K14: 5 | L14: =J14*K14 -> 10 | M14: 0 | N14: =L14-M14 -> 10 | O14: =N14/E14 -> 20
A15: 46132 | B15: TormaBum | C15: Habanero Hot Pepper | D15: 1 | E15: 1 | G15: 0 | H15: =D15-E15-F15 -> 0 | I15: cups | J15: 2 | K15: 5 | L15: =J15*K15 -> 10 | M15: 0 | N15: =L15-M15 -> 10 | O15: =N15/E15 -> 10
A16: 46140 | B16: TormaBum | C16: Local Hot Pepper | D16: 1 | E16: 1 | F16: =D16-E16 -> 0 | G16: =F16/D16 -> 0 | H16: =D16-E16-F16 -> 0 | I16: cups | J16: 3 | K16: 5 | L16: =J16*K16 -> 15 | M16: 0 | N16: =L16-M16 -> 15 | O16: =N16/E16 -> 15
A17: 46140 | B17: TormaBum | C17: Habanero Hot Pepper | D17: 0.5 | E17: 0.5 | F17: =D17-E17 -> 0 | G17: =F17/D17 -> 0 | H17: =D17-E17-F17 -> 0 | I17: cups | J17: 2 | K17: 5 | L17: =J17*K17 -> 10 | M17: 0 | N17: =L17-M17 -> 10 | O17: =N17/E17 -> 20
A18: 46140 | B18: TormaBum | C18: Eggplant | D18: 2.5 | E18: 2 | F18: =D18-E18 -> 0.5 | G18: =F18/D18 -> 0.2 | H18: =D18-E18-F18 -> 0 | I18: places | J18: 5 | K18: 3 | L18: =J18*K18 -> 15 | M18: 0 | N18: =L18-M18 -> 15 | O18: =N18/E18 -> 7.5 | P18: Spoilt in stores
A19: 46147 | B19: TormaBum | C19: Eggplant | D19: 2 | E19: 2 | F19: =D19-E19 -> 0 | G19: =F19/D19 -> 0 | H19: =D19-E19-F19 -> 0 | I19: places | J19: 1 dozen and 7 at 10 | L19: 20 | N19: =L19-M19 -> 20 | O19: =N19/E19 -> 10
A20: 46153 | B20: TormaBum | C20: Local Hot Pepper | D20: 1.5 | E20: 1.5 | F20: =D20-E20 -> 0 | G20: =F20/D20 -> 0 | H20: =D20-E20-F20 -> 0 | I20: cups | J20: 6 | K20: 5 | L20: =J20*K20 -> 30 | N20: =L20-M20 -> 30 | O20: =N20/E20 -> 20
A21: 46153 | B21: TormaBum | C21: Eggplant | D21: 2 | E21: 2 | F21: =D21-E21 -> 0 | G21: =F21/D21 -> 0 | H21: =D21-E21-F21 -> 0 | I21: places | J21: 3 | K21: 5 | L21: =J21*K21 -> 15 | N21: =L21-M21 -> 15 | O21: =N21/E21 -> 7.5
A22: 46153 | B22: TormaBum | C22: Garden Eggs | D22: 2 | E22: 2 | F22: =D22-E22 -> 0 | G22: =F22/D22 -> 0 | H22: =D22-E22-F22 -> 0 | I22: places | J22: 3 | K22: 5 | L22: =J22*K22 -> 15 | N22: =L22-M22 -> 15 | O22: =N22/E22 -> 7.5
A23: 46164 | B23: TormaBum | C23: Eggplant | D23: 5 | E23: 5 | F23: =D23-E23 -> 0 | G23: =F23/D23 -> 0 | H23: =D23-E23-F23 -> 0 | I23: places | J23: 10 | K23: 5 | L23: =J23*K23 -> 50 | N23: =L23-M23 -> 50 | O23: =N23/E23 -> 10
A24: 46164 | B24: TormaBum | C24: Garden Eggs | D24: 3.5 | E24: 3.5 | F24: =D24-E24 -> 0 | G24: =F24/D24 -> 0 | H24: =D24-E24-F24 -> 0 | I24: places | J24: 4 | K24: 5 | L24: =J24*K24 -> 20 | N24: =L24-M24 -> 20 | O24: =N24/E24 -> 5.7142857
A25: 46164 | B25: TormaBum | C25: Local Hot Pepper | D25: 4 | E25: 4 | F25: =D25-E25 -> 0 | G25: =F25/D25 -> 0 | H25: =D25-E25-F25 -> 0 | I25: cups | J25: 32 | K25: 5 | L25: =J25*K25 -> 160 | N25: =L25-M25 -> 160 | O25: =N25/E25 -> 40
F26: =D26-E26 -> 0 | G26: =F26/D26 -> #DIV/0! | L26: =J26*K26 -> 0 | N26: =L26-M26 -> 0 | O26: =N26/E26 -> #DIV/0!

Sheet Scenarios Profitability Tracker
A1: PROFITABILITY TRACKER - Market Scenario Comparison
A2: In blue is the actual amount we made from sales, the white represents the amounts we would have made if we sold in that market
A3: Vegetable Info | D3: Tormabum | G3: Bo | J3: Waterloo | M3: Summary
A4: Date | B4: Vegetable | C4: Quantity Delivered (kg) | D4: Revenue (NLE) | E4: Transport (NLE) | F4: Net (NLE) | G4: Revenue (NLE) | H4: Transport (NLE) | I4: Net (NLE) | J4: Revenue (NLE) | K4: Transport (NLE) | L4: Net (NLE) | M4: Tormabum Net/kg | N4: Bo Net/kg | O4: Waterloo Net/kg | P4: Best Market
A5: 46087 | B5: Local Hot Pepper | C5: 2.5 | Q5: orange house, no money recorded
A6: 46113 | B6: Habanero Hot Pepper | C6: 2 | D6: ='Market prices'!I11*C6 -> 85.470085 | E6: 0 | F6: =D6-E6 -> 85.470085 | G6: ='Daily Sales Record'!L4 -> 175 | H6: =(C6*70)/(SUM($C$6:$C$9)) -> 6.6666667 | I6: =G6-H6 -> 168.33333 | J6: ='Market prices'!I43*C6 -> 170.94017 | K6: =(C6*160)/(SUM($C$6:$C$9)) -> 15.238095 | L6: =J6-K6 -> 155.70208 | M6: =F6/C6 -> 42.735043 | N6: =I6/C6 -> 84.166667 | O6: =L6/C6 -> 77.851038
A7: 46113 | B7: Garden Eggs | C7: 5 | D7: ='Market prices'!I16*C7 -> 8.912656 | E7: 0 | F7: =D7-E7 -> 8.912656 | G7: ='Daily Sales Record'!L5 -> 85 | H7: =(C7*70)/(SUM($C$6:$C$9)) -> 16.666667 | I7: =G7-H7 -> 68.333333 | J7: ='Market prices'!I47*C7 -> 100.26738 | K7: =(C7*160)/(SUM($C$6:$C$9)) -> 38.095238 | L7: =J7-K7 -> 62.172142 | M7: =F7/C7 -> 1.7825312 | N7: =I7/C7 -> 13.666667 | O7: =L7/C7 -> 12.434428 | R7: Each trip to BO is approximately 70 leones
A8: 46113 | B8: Eggplant | C8: 11 | D8: ='Market prices'!I19*C8 -> 25.287356 | E8: 0 | F8: =D8-E8 -> 25.287356 | G8: ='Daily Sales Record'!L6 -> 44 | H8: =(C8*70)/(SUM($C$6:$C$9)) -> 36.666667 | I8: =G8-H8 -> 7.3333333 | J8: ='Market prices'!I51*C8 -> 337.16475 | K8: =(C8*160)/(SUM($C$6:$C$9)) -> 83.809524 | L8: =J8-K8 -> 253.35523 | M8: =F8/C8 -> 2.2988506 | N8: =I8/C8 -> 0.66666667 | O8: =L8/C8 -> 23.032293 | R8: Each trip to Waterloo is approximately 160 leones
A9: 46113 | B9: Local Hot Pepper | C9: 3 | D9: ='Market prices'!I9*C9 -> 110.29412 | E9: 0 | F9: =D9-E9 -> 110.29412 | G9: ='Daily Sales Record'!L7 -> 140 | H9: =(C9*70)/(SUM($C$6:$C$9)) -> 10 | I9: =G9-H9 -> 130 | J9: ='Market prices'!I42*C9 -> 220.58824 | K9: =(C9*160)/(SUM($C$6:$C$9)) -> 22.857143 | L9: =J9-K9 -> 197.73109 | M9: =F9/C9 -> 36.764706 | N9: =I9/C9 -> 43.333333 | O9: =L9/C9 -> 65.910364
A10: TOTAL | F10: =SUM(F6:F9) -> 229.96422 | I10: =SUM(I6:I9) -> 374 | L10: =SUM(L6:L9) -> 668.96054
A11: 46122 | B11: Local Hot Pepper | C11: 1 | D11: ='Daily Sales Record'!L8 -> 10 | E11: 0 | F11: =D11-E11 -> 10 | G11: ='Market prices'!I25*C11 -> 51.470588 | H11: 70 | I11: =G11-H11 -> -18.529412 | J11: ='Market prices'!I42*C11 -> 73.529412 | K11: =(C11*160)/(SUM(C11)) -> 160 | L11: =J11-K11 -> -86.470588 | M11: =F11/C11 -> 10 | N11: =I11/C11 -> -18.529412 | O11: =L11/C11 -> -86.470588
A12: TOTAL | F12: =SUM(F11) -> 10 | I12: =SUM(I11) -> -18.529412 | L12: =SUM(L11) -> -86.470588
A13: 46125 | B13: Garden Eggs | C13: 3 | D13: ='Daily Sales Record'!L9 -> 8 | E13: 0 | F13: =D13-E13 -> 8 | G13: ='Market prices'!I30*C13 -> 38.502674 | H13: =(C13*70)/(SUM($C$13:$C$16)) -> 18.103448 | I13: =G13-H13 -> 20.399226 | J13: ='Market prices'!I47*C13 -> 60.160428 | K13: =(C13*160)/(SUM($C$13:$C$16)) -> 41.37931 | L13: =J13-K13 -> 18.781117 | M13: =F13/C13 -> 2.6666667 | N13: =I13/C13 -> 6.7997418 | O13: =L13/C13 -> 6.2603725
A14: 46125 | B14: Eggplant | C14: 5 | D14: ='Daily Sales Record'!L10 -> 10 | E14: 0 | F14: =D14-E14 -> 10 | G14: ='Market prices'!I35*C14 -> 30.651341 | H14: =(C14*70)/(SUM($C$13:$C$16)) -> 30.172414 | I14: =G14-H14 -> 0.4789272 | J14: ='Market prices'!I51*C14 -> 153.2567 | K14: =(C14*160)/(SUM($C$13:$C$16)) -> 68.965517 | L14: =J14-K14 -> 84.291188 | M14: =F14/C14 -> 2 | N14: =I14/C14 -> 0.095785441 | O14: =L14/C14 -> 16.858238
A15: 46125 | B15: Local Hot Pepper | C15: 2.6 | D15: ='Daily Sales Record'!L11 -> 30 | E15: 0 | F15: =D15-E15 -> 30 | G15: ='Market prices'!I25*C15 -> 133.82353 | H15: =(C15*70)/(SUM($C$13:$C$16)) -> 15.689655 | I15: =G15-H15 -> 118.13387 | J15: ='Market prices'!I42*C15 -> 191.17647 | K15: =(C15*160)/(SUM($C$13:$C$16)) -> 35.862069 | L15: =J15-K15 -> 155.3144 | M15: =F15/C15 -> 11.538462 | N15: =I15/C15 -> 45.436105 | O15: =L15/C15 -> 59.736308
A16: 46125 | B16: Habanero Hot Pepper | C16: 1 | D16: 15 | E16: 0 | F16: =D16-E16 -> 15 | G16: ='Market prices'!I26*C16 -> 102.33918 | H16: =(C16*70)/(SUM($C$13:$C$16)) -> 6.0344828 | I16: =G16-H16 -> 96.304699 | J16: ='Market prices'!I43*C16 -> 85.470085 | K16: =(C16*160)/(SUM($C$13:$C$16)) -> 13.793103 | L16: =J16-K16 -> 71.676982 | M16: =F16/C16 -> 15 | N16: =I16/C16 -> 96.304699 | O16: =L16/C16 -> 71.676982
A17: TOTAL | F17: =SUM(F13:F16) -> 63 | I17: =SUM(I13:I16) -> 235.31673 | L17: =SUM(L13:L16) -> 330.06369
A18: 46132 | B18: Garden Eggs | C18: 3 | D18: ='Daily Sales Record'!L12 -> 10 | E18: 0 | F18: =D18-E18 -> 10 | G18: ='Market prices'!I30*C18 -> 38.502674 | H18: =(C18*70)/(SUM($C$18:$C$21)) -> 24.705882 | I18: =G18-H18 -> 13.796791 | J18: ='Market prices'!I47*C18 -> 60.160428 | K18: =(C18*160)/(SUM($C$18:$C$21)) -> 56.470588 | L18: =J18-K18 -> 3.6898396 | M18: =F18/C18 -> 3.3333333 | N18: =I18/C18 -> 4.5989305 | O18: =L18/C18 -> 1.2299465
A19: 46132 | B19: Eggplant | C19: 4 | D19: ='Daily Sales Record'!L13 -> 6 | E19: 0 | F19: =D19-E19 -> 6 | G19: ='Market prices'!I35*C19 -> 24.521073 | H19: =(C19*70)/(SUM($C$18:$C$21)) -> 32.941176 | I19: =G19-H19 -> -8.4201037 | J19: ='Market prices'!I51*C19 -> 122.60536 | K19: =(C19*160)/(SUM($C$18:$C$21)) -> 75.294118 | L19: =J19-K19 -> 47.311246 | M19: =F19/C19 -> 1.5 | N19: =I19/C19 -> -2.1050259 | O19: =L19/C19 -> 11.827812
A20: 46132 | B20: Local Hot Pepper | C20: 0.5 | D20: ='Daily Sales Record'!L14 -> 10 | E20: 0 | F20: =D20-E20 -> 10 | G20: ='Market prices'!I25*C20 -> 25.735294 | H20: =(C20*70)/(SUM($C$18:$C$21)) -> 4.1176471 | I20: =G20-H20 -> 21.617647 | J20: ='Market prices'!I42*C20 -> 36.764706 | K20: =(C20*160)/(SUM($C$18:$C$21)) -> 9.4117647 | L20: =J20-K20 -> 27.352941 | M20: =F20/C20 -> 20 | N20: =I20/C20 -> 43.235294 | O20: =L20/C20 -> 54.705882
A21: 46132 | B21: Habanero Hot Pepper | C21: 1 | D21: ='Daily Sales Record'!L15 -> 10 | E21: 0 | F21: =D21-E21 -> 10 | G21: ='Market prices'!I26*C21 -> 102.33918 | H21: =(C21*70)/(SUM($C$18:$C$21)) -> 8.2352941 | I21: =G21-H21 -> 94.103887 | J21: ='Market prices'!I43*C21 -> 85.470085 | K21: =(C21*160)/(SUM($C$18:$C$21)) -> 18.823529 | L21: =J21-K21 -> 66.646556 | M21: =F21/C21 -> 10 | N21: =I21/C21 -> 94.103887 | O21: =L21/C21 -> 66.646556
A22: TOTAL | F22: =SUM(F18:F21) -> 36 | I22: =SUM(I18:I21) -> 121.09822 | L22: =SUM(L18:L21) -> 145.00058
A23: 46140 | B23: Local Hot Pepper | C23: 1 | D23: ='Daily Sales Record'!L16 -> 15 | E23: 0 | F23: =D23-E23 -> 15 | G23: ='Market prices'!I25*C23 -> 51.470588 | H23: =(C23*70)/(SUM($C$23:$C$25)) -> 17.5 | I23: =G23-H23 -> 33.970588 | J23: ='Market prices'!I42*C23 -> 73.529412 | K23: =(C23*160)/(SUM($C$23:$C$25)) -> 40 | L23: =J23-K23 -> 33.529412 | M23: =F23/C23 -> 15 | N23: =I23/C23 -> 33.970588 | O23: =L23/C23 -> 33.529412
A24: 46140 | B24: Habanero Hot Pepper | C24: 0.5 | D24: ='Daily Sales Record'!L17 -> 10 | E24: 0 | F24: =D24-E24 -> 10 | G24: ='Market prices'!H26*C24 -> 92.105263 | H24: =(C24*70)/(SUM($C$23:$C$25)) -> 8.75 | I24: =G24-H24 -> 83.355263 | J24: ='Market prices'!I43*C24 -> 42.735043 | K24: =(C24*160)/(SUM($C$23:$C$25)) -> 20 | L24: =J24-K24 -> 22.735043 | M24: =F24/C24 -> 20 | N24: =I24/C24 -> 166.71053 | O24: =L24/C24 -> 45.470085
A25: 46140 | B25: Eggplant | C25: 2.5 | D25: ='Daily Sales Record'!L18 -> 15 | E25: 0 | F25: =D25-E25 -> 15 | G25: ='Market prices'!I35*C25 -> 15.32567 | H25: =(C25*70)/(SUM($C$23:$C$25)) -> 43.75 | I25: =G25-H25 -> -28.42433 | J25: ='Market prices'!I51*C25 -> 76.628352 | K25: =(C25*160)/(SUM($C$23:$C$25)) -> 100 | L25: =J25-K25 -> -23.371648 | M25: =F25/C25 -> 6 | N25: =I25/C25 -> -11.369732 | O25: =L25/C25 -> -9.348659
A26: TOTAL | F26: =SUM(F23:F25) -> 40 | I26: =SUM(I23:I25) -> 88.901522 | L26: =SUM(L23:L25) -> 32.892807
A27: 46147 | B27: Eggplant | C27: 2 | D27: ='Daily Sales Record'!L19 -> 20 | E27: 0 | F27: =D27-E27 -> 20 | G27: ='Market prices'!I35*C27 -> 12.260536 | H27: 70 | I27: =G27-H27 -> -57.739464 | J27: ='Market prices'!I51*C27 -> 61.302682 | K27: =(C27*160)/(SUM(C27)) -> 160 | L27: =J27-K27 -> -98.697318 | M27: =F27/C27 -> 10 | N27: =I27/C27 -> -28.869732 | O27: =L27/C27 -> -49.348659
A28: TOTAL | F28: =SUM(F27) -> 20 | I28: =SUM(I27) -> -57.739464 | L28: =SUM(L27) -> -98.697318
A29: 46331 | B29: Local Hot Pepper | C29: 1.5 | D29: ='Daily Sales Record'!L20 -> 30 | E29: 0 | F29: =D29-E29 -> 30 | G29: ='Market prices'!I25*C29 -> 77.205882 | H29: =(C29*70)/(SUM($C$29:$C$31)) -> 19.090909 | I29: =G29-H29 -> 58.114973 | J29: ='Market prices'!I42*C29 -> 110.29412 | K29: =(C29*160)/(SUM($C$29:$C$31)) -> 43.636364 | L29: =J29-K29 -> 66.657754 | M29: =F29/C29 -> 20 | N29: =I29/C29 -> 38.743316 | O29: =L29/C29 -> 44.438503
A30: 46331 | B30: Eggplant | C30: 2 | D30: ='Daily Sales Record'!L21 -> 15 | E30: 0 | F30: =D30-E30 -> 15 | G30: ='Market prices'!I35*C30 -> 12.260536 | H30: =(C30*70)/(SUM($C$29:$C$31)) -> 25.454545 | I30: =G30-H30 -> -13.194009 | J30: ='Market prices'!I51*C30 -> 61.302682 | K30: =(C30*160)/(SUM($C$29:$C$31)) -> 58.181818 | L30: =J30-K30 -> 3.1208638 | M30: =F30/C30 -> 7.5 | N30: =I30/C30 -> -6.5970045 | O30: =L30/C30 -> 1.5604319
A31: 46331 | B31: Garden Eggs | C31: 2 | D31: ='Daily Sales Record'!L22 -> 15 | E31: 0 | F31: =D31-E31 -> 15 | G31: ='Market prices'!I30*C31 -> 25.668449 | H31: =(C31*70)/(SUM($C$29:$C$31)) -> 25.454545 | I31: =G31-H31 -> 0.21390374 | J31: ='Market prices'!I47*C31 -> 40.106952 | K31: =(C31*160)/(SUM($C$29:$C$31)) -> 58.181818 | L31: =J31-K31 -> -18.074866 | M31: =F31/C31 -> 7.5 | N31: =I31/C31 -> 0.10695187 | O31: =L31/C31 -> -9.0374332
A32: TOTAL | F32: =SUM(F29:F31) -> 60 | I32: =SUM(I29:I31) -> 45.134868 | L32: =SUM(L29:L31) -> 51.703752
A33: 22/05/2026 | B33: Eggplant | C33: 5 | D33: ='Daily Sales Record'!L23 -> 50 | E33: 0 | F33: =D33-E33 -> 50 | G33: ='Market prices'!I35*C33 -> 30.651341 | H33: =(C33*70)/(SUM($C$33:$C$35)) -> 28 | I33: =G33-H33 -> 2.651341 | J33: ='Market prices'!I51*C33 -> 153.2567 | K33: =(C33*160)/(SUM($C$33:$C$35)) -> 64 | L33: =J33-K33 -> 89.256705 | M33: =F33/C33 -> 10 | N33: =I33/C33 -> 0.5302682 | O33: =L33/C33 -> 17.851341
A34: 22/05/2026 | B34: Garden Eggs | C34: 3.5 | D34: ='Daily Sales Record'!L24 -> 20 | E34: 0 | F34: =D34-E34 -> 20 | G34: ='Market prices'!I30*C34 -> 44.919786 | H34: =(C34*70)/(SUM($C$33:$C$35)) -> 19.6 | I34: =G34-H34 -> 25.319786 | J34: ='Market prices'!I47*C34 -> 70.187166 | K34: =(C34*160)/(SUM($C$33:$C$35)) -> 44.8 | L34: =J34-K34 -> 25.387166 | M34: =F34/C34 -> 5.7142857 | N34: =I34/C34 -> 7.2342246 | O34: =L34/C34 -> 7.2534759
A35: 22/05/2026 | B35: Local Hot Pepper | C35: 4 | D35: ='Daily Sales Record'!L25 -> 160 | E35: 0 | F35: =D35-E35 -> 160 | G35: ='Market prices'!I25*C35 -> 205.88235 | H35: =(C35*70)/(SUM($C$33:$C$35)) -> 22.4 | I35: =G35-H35 -> 183.48235 | J35: ='Market prices'!I42*C35 -> 294.11765 | K35: =(C35*160)/(SUM($C$33:$C$35)) -> 51.2 | L35: =J35-K35 -> 242.91765 | M35: =F35/C35 -> 40 | N35: =I35/C35 -> 45.870588 | O35: =L35/C35 -> 60.729412
A36: TOTAL | F36: =SUM(F33:F35) -> 230 | I36: =SUM(I33:I35) -> 211.45348 | L36: =SUM(L33:L35) -> 357.56152

Sheet Guide
A1: HOW THE WORKBOOK WORKS - Greenhouse Project
A2: SHEET 1 - Market Price Survey
A3: Purpose: | B3: Record prices across markets
A4: Key Column: | B4: "NLE per kg" - this is how you compare cross markets
A5: How to get NLE/kg | B5: Weigh a sample of the vegetable then enter kg per unit
A6: Tip: | B6: Record small and large sizes separately
A8: SHEET 2 - Daily Sales Record
A9: Purpose: | B9: Log in sales made by FOOP
A10: Key column:

Sheet Weighing Reference
A1: WEIGHING REFERENCE - Greenhouse Project
A2: To standardize units, weigh a sample of each vegetable to determine how much adds up to 1kg for easy comparisn of prices
A3: HOW TO MEASURE: Pick 5 vegetables of the same size →weigh them together (in kg) →divide 5 by that weight = pieces per kg.→ e.g. 5 small eggplants weigh 0.6kg, therefore 5/0.6 = 8.3 pieces/kg.
A4: Section 1 - Vegetables sold by piece/display (eggplants, okra, tomato, cucumber, cabbage, garden eggs)
A5: Vegetable | B5: Size (Small/Medium/Large) | C5: Sample count (# weighed) | D5: Total weight of sample (kg) | E5: Pieces per kg | F5: kg per piece | G5: Date measured | H5: Notes
A6: Tomato | B6: small | C6: 3 | D6: 0.221 | E6: =C6/D6 -> 13.574661 | F6: =D6/C6 -> 0.073666667 | G6: 46208
A7: Tomato | B7: medium | C7: 5 | E7: =C7/D7 -> #DIV/0! | F7: =D7/C7 -> 0
A8: Tomato | B8: big | C8: 3 | D8: 0.453 | E8: =C8/D8 -> 6.6225166 | F8: =D8/C8 -> 0.151 | G8: 46178
A9: Eggplant | B9: small | C9: 5 | E9: =C9/D9 -> #DIV/0! | F9: =D9/C9 -> 0
A10: Eggplant | B10: medium | C10: 4 | D10: 0.435 | E10: =C10/D10 -> 9.1954023 | F10: =D10/C10 -> 0.10875 | G10: 46208
A11: Eggplant | B11: big | C11: 5 | E11: =C11/D11 -> #DIV/0! | F11: =D11/C11 -> 0
A12: Garden Eggs | B12: small | C12: 4 | D12: 0.086 | E12: =C12/D12 -> 46.511628 | F12: =D12/C12 -> 0.0215 | G12: 46147
A13: Garden Eggs | B13: medium | C13: 3 | D13: 0.187 | E13: =C13/D13 -> 16.042781 | F13: =D13/C13 -> 0.062333333 | G13: 46147 | J13: =5000/187 -> 26.737968
A14: Garden Eggs | B14: big | C14: 5 | E14: =C14/D14 -> #DIV/0! | F14: =D14/C14 -> 0
A15: Cucumber | B15: small | C15: 5 | E15: =C15/D15 -> #DIV/0! | F15: =D15/C15 -> 0
A16: Cucumber | B16: medium | C16: 3 | D16: 0.426 | E16: =C16/D16 -> 7.0422535 | F16: =D16/C16 -> 0.142 | G16: 46208
A17: Okra | B17: any | C17: 4 | D17: 0.063 | E17: =C17/D17 -> 63.492063 | F17: =D17/C17 -> 0.01575 | G17: 46147 | L17: =1000/136 -> 7.3529412
A18: Carrot | B18: small | C18: 5 | E18: =C18/D18 -> #DIV/0! | F18: =D18/C18 -> 0 | L18: =3000/136 -> 22.058824
A19: Carrot | B19: medium | C19: 3 | D19: 0.366 | E19: =C19/D19 -> 8.1967213 | F19: =D19/C19 -> 0.122 | G19: 46208 | L19: =2600/136 -> 19.117647
A20: Carrot | B20: big | C20: 2 | D20: 0.293 | E20: =C20/D20 -> 6.8259386 | F20: =D20/C20 -> 0.1465 | G20: 46178
A21: Green Pepper | B21: big | C21: 2 | D21: =188/1000 -> 0.188 | E21: =C21/D21 -> 10.638298 | F21: =D21/C21 -> 0.094 | G21: 46208
A22: Green Pepper | B22: medium | C22: 2 | D22: 0.1 | E22: =C22/D22 -> 20 | F22: =D22/C22 -> 0.05 | G22: 46208
A23: Section 2 - Vegetables sold by cup/tie (krainkrain, hot pepper)
A24: Vegetable | B24: Market Unit (cup/tie/bundle) | C24: Sample count (# weighed) | D24: Total weight of sample (kg) | E24: Units per kg | F24: Date Measured | G24: Notes
A25: KrainKrain | B25: tie | C25: 1 | D25: 0.5 | E25: =C25/D25 -> 2 | F25: 46208
A26: Local Hot Pepper | B26: cup | C26: 1 | D26: 0.136 | E26: =C26/D26 -> 7.3529412 | F26: 46147
A27: Habanerro Pepper | B27: pieces | C27: 7 | D27: 0.038 | E27: =C27/D27 -> 184.21053 | F27: 46178
A28: Habanerro Pepper | B28: cup | C28: 1 | D28: 0.117 | E28: =C28/D28 -> 8.5470085 | F28: 46178
